<?xml version="1.0"?>
<robot name="fourwheel_robot">
	<link name="body_link">
		<parent link="world"/>
		<visual>
			<origin rpy="0 0 0" xyz="0 0 0"/>
			<geometry>
				<box size="1 0.6 0.3" />
			</geometry>
			
			<material name="red">
				<color rgba="1 0 0 1"/>
			</material>
		</visual>
	</link>

	<!-- Robot wheels -->
	<!-- Back right wheel -->
	<joint name="wheel1_joint" type="continuous" >
		<parent link="body_link"/>
		<child link="wheel1_link"/>
		<origin xyz="-0.35 -0.3 -0.1" rpy="0 0 0" />
		<axis xyz="0 1 0"/>
	</joint>
	<link name="wheel1_link">
		<visual>
			<origin rpy="1.570795 0 0" xyz="0 0 0"/> <!-- 90 degrees-->
			<geometry>
				<cylinder length="0.1" radius="0.15"/>
			</geometry>

			<material name="yellow">
				<color rgba="1 1 0 1"/>
			</material>
		</visual>
	</link>

	<!-- Back left wheel -->
	<joint name="wheel2_joint" type="continuous" >
		<parent link="body_link"/>
		<child link="wheel2_link"/>
		<origin xyz="0.35 -0.3 -0.1" rpy="0 0 0" />
		<axis xyz="0 1 0"/>
	</joint>
	<link name="wheel2_link">
		<visual>
			<origin rpy="1.570795 0 0" xyz="0 0 0"/>						<geometry>
				<cylinder length="0.1" radius="0.15"/>
			</geometry>

			<material name="yellow">
				<color rgba="1 1 0 1"/>
			</material>
		</visual>
	</link>

	<!-- Front right wheel -->
	<joint name="wheel3_joint" type="continuous" >
		<parent link="body_link"/>
		<child link="wheel3_link"/>
		<origin xyz="-0.35 0.3 -0.1" rpy="0 0 0" />
		<axis xyz="0 1 0"/>
	</joint>
	<link name="wheel3_link">
		<visual>
			<origin rpy="1.570795 0 0" xyz="0 0 0"/> <!-- 90 degrees-->
			<geometry>
				<cylinder length="0.1" radius="0.15"/>
			</geometry>

			<material name="yellow">
				<color rgba="1 1 0 1"/>
			</material>
		</visual>
	</link>

	<!-- Front left wheel -->
	<joint name="wheel4_joint" type="continuous" >
		<parent link="body_link"/>
		<child link="wheel4_link"/>
		<origin xyz="0.35 0.3 -0.1" rpy="0 0 0" />
		<axis xyz="0 1 0"/>
	</joint>
	<link name="wheel4_link">
		<visual>
			<origin rpy="1.570795 0 0" xyz="0 0 0"/>						<geometry>
				<cylinder length="0.1" radius="0.15"/>
			</geometry>

			<material name="yellow">
				<color rgba="1 1 0 1"/>
			</material>
		</visual>
	</link>
</robot>
